Workbook

Sheet DASHBOARD
A1: DASHBOARD — VIABILIDADE ECONÔMICA DO EMPREENDIMENTO
A2: =CONFIG!C4 -> Residencial Parque Verde
A3: =CONCATENATE("Início: ",TEXT(CONFIG!C6,"DD/MM/YYYY")," | Prazo: ",TEXT(CONFIG!C7,"0")," meses | Atualizado em: ",TEXT(TODAY(),"DD/MM/YYYY")) -> Início: 01/01/YYYY | Prazo: 30 meses | Atualizado em: 29/03/YYYY
B5: 💰 MARGEM DO EMPREENDIMENTO | H5: 📈 ROI DO EMPREENDIMENTO
B6: INDICADOR | C6: VALOR | D6: META | E6: STATUS | H6: INDICADOR | I6: VALOR | J6: META | K6: STATUS
B7: VGV Total (R$) | C7: =RECEITAS!G9 -> 6120000 | D7: =CONFIG!C8 -> 17000000 | E7: — | H7: Capital Próprio (R$) | I7: =CONFIG!C10 -> 3500000 | J7: =CONFIG!C10 -> 3500000 | K7: —
B8: Custo Realizado (R$) | C8: =CUSTOS!D12 -> 5755000 | D8: =CONFIG!C9 -> 11900000 | E8: — | H8: Lucro Bruto (R$) | I8: =C9 -> 365000 | J8: — | K8: —
B9: Lucro Bruto (R$) | C9: =C7-C8 -> 365000 | D9: =D7-D8 -> 5100000 | E9: — | H9: ROI Total (%) | I9: =IFERROR(C9/CONFIG!C10,0) -> 0.10428571 | J9: =CONFIG!C15 -> 0.4 | K9: =IF(I9>=J9,"✅ OK",IF(I9>=J9*0.8,"⚠️ Atenção","🔴 Crítico")) -> 🔴 Crítico
B10: Margem Bruta (%) | C10: =IFERROR(C9/C7,0) -> 0.059640523 | D10: =CONFIG!C14 -> 0.25 | E10: =IF(C10>=D10,"✅ OK",IF(C10>=D10*0.8,"⚠️ Atenção","🔴 Crítico")) -> 🔴 Crítico | H10: Prazo Previsto (meses) | I10: =CONFIG!C7 -> 30 | J10: =CONFIG!C16 -> 30 | K10: —
B11: Custo/VGV (%) | C11: =IFERROR(C8/C7,0) -> 0.94035948 | D11: =IFERROR(D8/D7,0) -> 0.7 | E11: — | H11: ROI Anualizado (%) | I11: =IFERROR((1+I9)^(12/CONFIG!C7)-1,0) -> 0.040477233 | J11: — | K11: —
B13: 🔍 CUSTO REALIZADO vs. PREVISTO POR CATEGORIA
B14: CATEGORIA | C14: ORÇADO (R$) | D14: REALIZADO (R$) | E14: DESVIO (R$) | F14: DESVIO (%) | G14: STATUS | H14: % EXEC.
B15: Terreno | C15: =CUSTOS!C4 -> 2500000 | D15: =CUSTOS!D4 -> 2500000 | E15: =D15-C15 -> 0 | F15: =IFERROR(E15/C15,0) -> 0 | G15: =IF(F15<=0,"✅ OK",IF(F15<=0.05,"⚠️ Atenção","🔴 Estourou")) -> ✅ OK | H15: =IFERROR(D15/C15,0) -> 1
B16: Projetos e Aprovações | C16: =CUSTOS!C5 -> 350000 | D16: =CUSTOS!D5 -> 385000 | E16: =D16-C16 -> 35000 | F16: =IFERROR(E16/C16,0) -> 0.1 | G16: =IF(F16<=0,"✅ OK",IF(F16<=0.05,"⚠️ Atenção","🔴 Estourou")) -> 🔴 Estourou | H16: =IFERROR(D16/C16,0) -> 1.1
B17: Obra Civil | C17: =CUSTOS!C6 -> 5800000 | D17: =CUSTOS!D6 -> 1950000 | E17: =D17-C17 -> -3850000 | F17: =IFERROR(E17/C17,0) -> -0.6637931 | G17: =IF(F17<=0,"✅ OK",IF(F17<=0.05,"⚠️ Atenção","🔴 Estourou")) -> ✅ OK | H17: =IFERROR(D17/C17,0) -> 0.3362069
B18: Instalações | C18: =CUSTOS!C7 -> 900000 | D18: =CUSTOS!D7 -> 310000 | E18: =D18-C18 -> -590000 | F18: =IFERROR(E18/C18,0) -> -0.65555556 | G18: =IF(F18<=0,"✅ OK",IF(F18<=0.05,"⚠️ Atenção","🔴 Estourou")) -> ✅ OK | H18: =IFERROR(D18/C18,0) -> 0.34444444
B19: Marketing | C19: =CUSTOS!C8 -> 350000 | D19: =CUSTOS!D8 -> 180000 | E19: =D19-C19 -> -170000 | F19: =IFERROR(E19/C19,0) -> -0.48571429 | G19: =IF(F19<=0,"✅ OK",IF(F19<=0.05,"⚠️ Atenção","🔴 Estourou")) -> ✅ OK | H19: =IFERROR(D19/C19,0) -> 0.51428571
B20: Comercialização | C20: =CUSTOS!C9 -> 595000 | D20: =CUSTOS!D9 -> 210000 | E20: =D20-C20 -> -385000 | F20: =IFERROR(E20/C20,0) -> -0.64705882 | G20: =IF(F20<=0,"✅ OK",IF(F20<=0.05,"⚠️ Atenção","🔴 Estourou")) -> ✅ OK | H20: =IFERROR(D20/C20,0) -> 0.35294118
B21: Financeiro (Juros/CET) | C21: =CUSTOS!C10 -> 405000 | D21: =CUSTOS!D10 -> 95000 | E21: =D21-C21 -> -310000 | F21: =IFERROR(E21/C21,0) -> -0.7654321 | G21: =IF(F21<=0,"✅ OK",IF(F21<=0.05,"⚠️ Atenção","🔴 Estourou")) -> ✅ OK | H21: =IFERROR(D21/C21,0) -> 0.2345679
B22: Outros | C22: =CUSTOS!C11 -> 450000 | D22: =CUSTOS!D11 -> 125000 | E22: =D22-C22 -> -325000 | F22: =IFERROR(E22/C22,0) -> -0.72222222 | G22: =IF(F22<=0,"✅ OK",IF(F22<=0.05,"⚠️ Atenção","🔴 Estourou")) -> ✅ OK | H22: =IFERROR(D22/C22,0) -> 0.27777778
B23: TOTAL GERAL | C23: =CUSTOS!C12 -> 11350000 | D23: =CUSTOS!D12 -> 5755000 | E23: =D23-C23 -> -5595000 | F23: =IFERROR(E23/C23,0) -> -0.49295154 | G23: =IF(F23<=0,"✅ OK",IF(F23<=0.05,"⚠️ Atenção","🔴 Estourou")) -> ✅ OK | H23: =IFERROR(D23/C23,0) -> 0.50704846
B25: 📅 PRAZO REAL vs. PLANEJADO — FASES DO EMPREENDIMENTO
B26: FASE | C26: PLANEJADO | D26: REALIZADO | E26: DESVIO | F26: STATUS
B27: 1. Aquisição do Terreno | C27: =CRONOGRAMA!C4 -> 46023 | D27: =IF(CRONOGRAMA!D4="","—",CRONOGRAMA!D4) -> 46023 | E27: =CRONOGRAMA!E4 -> 0 | F27: =CRONOGRAMA!F4 -> ✅ No Prazo
B28: 2. Projeto Arquitetônico | C28: =CRONOGRAMA!C5 -> 46054 | D28: =IF(CRONOGRAMA!D5="","—",CRONOGRAMA!D5) -> 46068 | E28: =CRONOGRAMA!E5 -> 14 | F28: =CRONOGRAMA!F5 -> ⚠️ Atraso Leve
B29: 3. Aprovações e Licenças | C29: =CRONOGRAMA!C6 -> 46113 | D29: =IF(CRONOGRAMA!D6="","—",CRONOGRAMA!D6) -> — | E29: =CRONOGRAMA!E6 | F29: =CRONOGRAMA!F6 -> ⏳ Pendente
B30: 4. Lançamento Comercial | C30: =CRONOGRAMA!C7 -> 46143 | D30: =IF(CRONOGRAMA!D7="","—",CRONOGRAMA!D7) -> — | E30: =CRONOGRAMA!E7 | F30: =CRONOGRAMA!F7 -> ⏳ Pendente
B31: 5. Obra — Início | C31: =CRONOGRAMA!C8 -> 46204 | D31: =IF(CRONOGRAMA!D8="","—",CRONOGRAMA!D8) -> — | E31: =CRONOGRAMA!E8 | F31: =CRONOGRAMA!F8 -> ⏳ Pendente
B32: 6. Obra — Conclusão | C32: =CRONOGRAMA!C9 -> 46753 | D32: =IF(CRONOGRAMA!D9="","—",CRONOGRAMA!D9) -> — | E32: =CRONOGRAMA!E9 | F32: =CRONOGRAMA!F9 -> ⏳ Pendente
B33: 7. Habite-se | C33: =CRONOGRAMA!C10 -> 46784 | D33: =IF(CRONOGRAMA!D10="","—",CRONOGRAMA!D10) -> — | E33: =CRONOGRAMA!E10 | F33: =CRONOGRAMA!F10 -> ⏳ Pendente
B34: 8. Entrega de Chaves | C34: =CRONOGRAMA!C11 -> 46935 | D34: =IF(CRONOGRAMA!D11="","—",CRONOGRAMA!D11) -> — | E34: =CRONOGRAMA!E11 | F34: =CRONOGRAMA!F11 -> ⏳ Pendente
B35: Desvio Total Acumulado (dias) | F35: =CRONOGRAMA!F18 -> -
B37: 🏗️ RANKING DE FORNECEDORES — TOP 10 POR SCORE DE RISCO
B38: RANK | C38: FORNECEDOR | D38: CATEGORIA | E38: ORÇADO (R$) | F38: REALIZADO (R$) | G38: DESV. CUSTO % | H38: DESV. PRAZO % | I38: SCORE
B39: 1 | C39: =IFERROR(INDEX(FORNECEDORES!$B$4:$B$23,MATCH(1,FORNECEDORES!$K$4:$K$23,0)),"") -> Assessoria Jurídica | D39: =IFERROR(INDEX(FORNECEDORES!$C$4:$C$23,MATCH(1,FORNECEDORES!$K$4:$K$23,0)),"") -> Aprovações | E39: =IFERROR(INDEX(FORNECEDORES!$D$4:$D$23,MATCH(1,FORNECEDORES!$K$4:$K$23,0)),"") -> 80000 | F39: =IFERROR(INDEX(FORNECEDORES!$E$4:$E$23,MATCH(1,FORNECEDORES!$K$4:$K$23,0)),"") -> 90000 | G39: =IFERROR(INDEX(FORNECEDORES!$H$4:$H$23,MATCH(1,FORNECEDORES!$K$4:$K$23,0)),"") -> 0.125 | H39: =IFERROR(INDEX(FORNECEDORES!$I$4:$I$23,MATCH(1,FORNECEDORES!$K$4:$K$23,0)),"") -> 0.37777778 | I39: =IFERROR(INDEX(FORNECEDORES!$J$4:$J$23,MATCH(1,FORNECEDORES!$K$4:$K$23,0)),"") -> 25.138889
B40: 2 | C40: =IFERROR(INDEX(FORNECEDORES!$B$4:$B$23,MATCH(2,FORNECEDORES!$K$4:$K$23,0)),"") -> Escritório Arq. XYZ | D40: =IFERROR(INDEX(FORNECEDORES!$C$4:$C$23,MATCH(2,FORNECEDORES!$K$4:$K$23,0)),"") -> Projetos | E40: =IFERROR(INDEX(FORNECEDORES!$D$4:$D$23,MATCH(2,FORNECEDORES!$K$4:$K$23,0)),"") -> 180000 | F40: =IFERROR(INDEX(FORNECEDORES!$E$4:$E$23,MATCH(2,FORNECEDORES!$K$4:$K$23,0)),"") -> 210000 | G40: =IFERROR(INDEX(FORNECEDORES!$H$4:$H$23,MATCH(2,FORNECEDORES!$K$4:$K$23,0)),"") -> 0.16666667 | H40: =IFERROR(INDEX(FORNECEDORES!$I$4:$I$23,MATCH(2,FORNECEDORES!$K$4:$K$23,0)),"") -> 0.25 | I40: =IFERROR(INDEX(FORNECEDORES!$J$4:$J$23,MATCH(2,FORNECEDORES!$K$4:$K$23,0)),"") -> 20.833333
B41: 3 | C41: =IFERROR(INDEX(FORNECEDORES!$B$4:$B$23,MATCH(3,FORNECEDORES!$K$4:$K$23,0)),"") -> Gráfica & Comunicação | D41: =IFERROR(INDEX(FORNECEDORES!$C$4:$C$23,MATCH(3,FORNECEDORES!$K$4:$K$23,0)),"") -> Marketing | E41: =IFERROR(INDEX(FORNECEDORES!$D$4:$D$23,MATCH(3,FORNECEDORES!$K$4:$K$23,0)),"") -> 40000 | F41: =IFERROR(INDEX(FORNECEDORES!$E$4:$E$23,MATCH(3,FORNECEDORES!$K$4:$K$23,0)),"") -> 50000 | G41: =IFERROR(INDEX(FORNECEDORES!$H$4:$H$23,MATCH(3,FORNECEDORES!$K$4:$K$23,0)),"") -> 0.25 | H41: =IFERROR(INDEX(FORNECEDORES!$I$4:$I$23,MATCH(3,FORNECEDORES!$K$4:$K$23,0)),"") -> 0.1 | I41: =IFERROR(INDEX(FORNECEDORES!$J$4:$J$23,MATCH(3,FORNECEDORES!$K$4:$K$23,0)),"") -> 17.5
B42: 4 | C42: =IFERROR(INDEX(FORNECEDORES!$B$4:$B$23,MATCH(4,FORNECEDORES!$K$4:$K$23,0)),"") -> Topografia & Sondagem | D42: =IFERROR(INDEX(FORNECEDORES!$C$4:$C$23,MATCH(4,FORNECEDORES!$K$4:$K$23,0)),"") -> Outros | E42: =IFERROR(INDEX(FORNECEDORES!$D$4:$D$23,MATCH(4,FORNECEDORES!$K$4:$K$23,0)),"") -> 60000 | F42: =IFERROR(INDEX(FORNECEDORES!$E$4:$E$23,MATCH(4,FORNECEDORES!$K$4:$K$23,0)),"") -> 65000 | G42: =IFERROR(INDEX(FORNECEDORES!$H$4:$H$23,MATCH(4,FORNECEDORES!$K$4:$K$23,0)),"") -> 0.083333333 | H42: =IFERROR(INDEX(FORNECEDORES!$I$4:$I$23,MATCH(4,FORNECEDORES!$K$4:$K$23,0)),"") -> 0.16666667 | I42: =IFERROR(INDEX(FORNECEDORES!$J$4:$J$23,MATCH(4,FORNECEDORES!$K$4:$K$23,0)),"") -> 12.5
B43: 5 | C43: =IFERROR(INDEX(FORNECEDORES!$B$4:$B$23,MATCH(5,FORNECEDORES!$K$4:$K$23,0)),"") -> Inst. Elétrica Ltda | D43: =IFERROR(INDEX(FORNECEDORES!$C$4:$C$23,MATCH(5,FORNECEDORES!$K$4:$K$23,0)),"") -> Instalações | E43: =IFERROR(INDEX(FORNECEDORES!$D$4:$D$23,MATCH(5,FORNECEDORES!$K$4:$K$23,0)),"") -> 450000 | F43: =IFERROR(INDEX(FORNECEDORES!$E$4:$E$23,MATCH(5,FORNECEDORES!$K$4:$K$23,0)),"") -> 185000 | G43: =IFERROR(INDEX(FORNECEDORES!$H$4:$H$23,MATCH(5,FORNECEDORES!$K$4:$K$23,0)),"") -> 0 | H43: =IFERROR(INDEX(FORNECEDORES!$I$4:$I$23,MATCH(5,FORNECEDORES!$K$4:$K$23,0)),"") -> 0.066666667 | I43: =IFERROR(INDEX(FORNECEDORES!$J$4:$J$23,MATCH(5,FORNECEDORES!$K$4:$K$23,0)),"") -> 3.3333333
B44: 6 | C44: =IFERROR(INDEX(FORNECEDORES!$B$4:$B$23,MATCH(6,FORNECEDORES!$K$4:$K$23,0)),"") -> Construtora ABC | D44: =IFERROR(INDEX(FORNECEDORES!$C$4:$C$23,MATCH(6,FORNECEDORES!$K$4:$K$23,0)),"") -> Obra Civil | E44: =IFERROR(INDEX(FORNECEDORES!$D$4:$D$23,MATCH(6,FORNECEDORES!$K$4:$K$23,0)),"") -> 5800000 | F44: =IFERROR(INDEX(FORNECEDORES!$E$4:$E$23,MATCH(6,FORNECEDORES!$K$4:$K$23,0)),"") -> 1950000 | G44: =IFERROR(INDEX(FORNECEDORES!$H$4:$H$23,MATCH(6,FORNECEDORES!$K$4:$K$23,0)),"") -> 0 | H44: =IFERROR(INDEX(FORNECEDORES!$I$4:$I$23,MATCH(6,FORNECEDORES!$K$4:$K$23,0)),"") -> 0.046296296 | I44: =IFERROR(INDEX(FORNECEDORES!$J$4:$J$23,MATCH(6,FORNECEDORES!$K$4:$K$23,0)),"") -> 2.3148148
...

Sheet CONFIG
A1: ⚙️ CONFIGURAÇÕES DO EMPREENDIMENTO
A3: DADOS DO EMPREENDIMENTO
B4: Nome do Empreendimento | C4: Residencial Parque Verde
B5: Endereço | C5: Rua das Flores, 100 – SP/SP
B6: Data de Início | C6: 46023
B7: Prazo Previsto (meses) | C7: 30
B8: VGV Total Projetado (R$) | C8: 17000000
B9: Custo Total Orçado (R$) | C9: 11900000
B10: Capital Próprio Investido (R$) | C10: 3500000
A13: METAS DO PROJETO
B14: Meta de Margem Bruta (%) | C14: 0.25
B15: Meta de ROI (%) | C15: 0.4
B16: Meta de Prazo (meses) | C16: 30
A19: PARÂMETROS — SCORE DE FORNECEDORES
B20: Peso — Desvio de Custo | C20: 0.5
B21: Peso — Desvio de Prazo | C21: 0.5
B22: Validação (deve = 100%) | C22: =C20+C21 -> 1
A25: LEGENDA DE CORES — CONVENÇÃO FINANCEIRA
B26: Azul = Entrada de dados (o usuário preenche)
B27: Verde = Fórmula com link de outra aba
B28: Preto = Fórmula calculada automaticamente
B29: Amarelo = Célula de atenção / validação

Sheet RECEITAS
A1: 🏠 RECEITAS — UNIDADES E CRONOGRAMA DE VENDAS
B3: TABELA DE UNIDADES
B4: TIPO DE UNIDADE | C4: QTD | D4: PREÇO UNIT. (R$) | E4: VGV UNITÁRIO (R$) | F4: % VENDIDO | G4: RECEITA RECEBIDA (R$)
B5: Studio (35 m²) | C5: 8 | D5: 350000 | E5: =C5*D5 -> 2800000 | F5: 0.6 | G5: =E5*F5 -> 1680000
B6: 2 Quartos (65 m²) | C6: 15 | D6: 580000 | E6: =C6*D6 -> 8700000 | F6: 0.4 | G6: =E6*F6 -> 3480000
B7: 3 Quartos (90 m²) | C7: 8 | D7: 600000 | E7: =C7*D7 -> 4800000 | F7: 0.2 | G7: =E7*F7 -> 960000
B8: Cobertura (120 m²) | C8: 2 | D8: 950000 | E8: =C8*D8 -> 1900000 | F8: 0 | G8: =E8*F8 -> 0
B9: TOTAL | C9: =SUM(C5:C8) -> 33 | E9: =SUM(E5:E8) -> 18200000 | F9: =IFERROR(G9/E9,0) -> 0.33626374 | G9: =SUM(G5:G8) -> 6120000
B11: RESUMO FINANCEIRO DE RECEITAS
B12: VGV Total (todas as unidades) | G12: =E9 -> 18200000
B13: Receita já comprometida (vendas realizadas) | G13: =G9 -> 6120000
B14: % do VGV vendido | G14: =IFERROR(G9/E9,0) -> 0.33626374
B15: Receita a realizar (unidades disponíveis) | G15: =E9-G9 -> 12080000
B18: CRONOGRAMA DE RECEBIMENTOS (R$)
B19: TIPO | C19: Sinal (Entrada) | D19: Parcelas Obra | E19: Financ. Banco | F19: Chaves | G19: TOTAL
B20: Studio (35 m²) | C20: 70000 | D20: 130000 | E20: 900000 | F20: 60000 | G20: =C20+D20+E20+F20 -> 1160000
B21: 2 Quartos (65 m²) | C21: 139200 | D21: 232000 | E21: 2088000 | F21: 0 | G21: =C21+D21+E21+F21 -> 2459200
B22: 3 Quartos (90 m²) | C22: 72000 | D22: 120000 | E22: 768000 | F22: 0 | G22: =C22+D22+E22+F22 -> 960000
B23: Cobertura (120 m²) | C23: 0 | D23: 0 | E23: 0 | F23: 0 | G23: =C23+D23+E23+F23 -> 0
B24: TOTAL | C24: =SUM(C20:C23) -> 281200 | D24: =SUM(D20:D23) -> 482000 | E24: =SUM(E20:E23) -> 3756000 | F24: =SUM(F20:F23) -> 60000 | G24: =SUM(G20:G23) -> 4579200

Sheet CUSTOS
A1: 💰 CUSTOS — ORÇADO vs. REALIZADO
A2: Preencha as colunas Orçado (azul) e Realizado (azul). Desvios são calculados automaticamente.
B3: CATEGORIA | C3: ORÇADO (R$) | D3: REALIZADO (R$) | E3: % EXEC. | F3: DESVIO (R$) | G3: DESVIO (%)
B4: Terreno | C4: 2500000 | D4: 2500000 | E4: =IFERROR(D4/C4,0) -> 1 | F4: =D4-C4 -> 0 | G4: =IFERROR((D4-C4)/C4,0) -> 0
B5: Projetos e Aprovações | C5: 350000 | D5: 385000 | E5: =IFERROR(D5/C5,0) -> 1.1 | F5: =D5-C5 -> 35000 | G5: =IFERROR((D5-C5)/C5,0) -> 0.1
B6: Obra Civil | C6: 5800000 | D6: 1950000 | E6: =IFERROR(D6/C6,0) -> 0.3362069 | F6: =D6-C6 -> -3850000 | G6: =IFERROR((D6-C6)/C6,0) -> -0.6637931
B7: Instalações | C7: 900000 | D7: 310000 | E7: =IFERROR(D7/C7,0) -> 0.34444444 | F7: =D7-C7 -> -590000 | G7: =IFERROR((D7-C7)/C7,0) -> -0.65555556
B8: Marketing | C8: 350000 | D8: 180000 | E8: =IFERROR(D8/C8,0) -> 0.51428571 | F8: =D8-C8 -> -170000 | G8: =IFERROR((D8-C8)/C8,0) -> -0.48571429
B9: Comercialização | C9: 595000 | D9: 210000 | E9: =IFERROR(D9/C9,0) -> 0.35294118 | F9: =D9-C9 -> -385000 | G9: =IFERROR((D9-C9)/C9,0) -> -0.64705882
B10: Financeiro (Juros/CET) | C10: 405000 | D10: 95000 | E10: =IFERROR(D10/C10,0) -> 0.2345679 | F10: =D10-C10 -> -310000 | G10: =IFERROR((D10-C10)/C10,0) -> -0.7654321
B11: Outros | C11: 450000 | D11: 125000 | E11: =IFERROR(D11/C11,0) -> 0.27777778 | F11: =D11-C11 -> -325000 | G11: =IFERROR((D11-C11)/C11,0) -> -0.72222222
B12: TOTAL GERAL | C12: =SUM(C4:C11) -> 11350000 | D12: =SUM(D4:D11) -> 5755000 | E12: =IFERROR(D12/C12,0) -> 0.50704846 | F12: =D12-C12 -> -5595000 | G12: =IFERROR((D12-C12)/C12,0) -> -0.49295154
B14: Fonte: atualize os valores realizados mensalmente conforme contratos e medições de obra.

Sheet CRONOGRAMA
A1: 📅 CRONOGRAMA — PRAZO PLANEJADO vs. REALIZADO
A2: Preencha a Data Real conforme a fase for concluída. O desvio e status são calculados automaticamente.
B3: FASE DO EMPREENDIMENTO | C3: DATA PLANEJADA | D3: DATA REAL | E3: DESVIO (dias) | F3: STATUS
B4: 1. Aquisição do Terreno | C4: 46023 | D4: 46023 | E4: =IF(D4="","",D4-C4) -> 0 | F4: =IF(D4="","⏳ Pendente",IF(D4<=C4,"✅ No Prazo",IF(D4-C4<=15,"⚠️ Atraso Leve","🔴 Atrasado"))) -> ✅ No Prazo
B5: 2. Projeto Arquitetônico | C5: 46054 | D5: 46068 | E5: =IF(D5="","",D5-C5) -> 14 | F5: =IF(D5="","⏳ Pendente",IF(D5<=C5,"✅ No Prazo",IF(D5-C5<=15,"⚠️ Atraso Leve","🔴 Atrasado"))) -> ⚠️ Atraso Leve
B6: 3. Aprovações e Licenças | C6: 46113 | E6: =IF(D6="","",D6-C6) | F6: =IF(D6="","⏳ Pendente",IF(D6<=C6,"✅ No Prazo",IF(D6-C6<=15,"⚠️ Atraso Leve","🔴 Atrasado"))) -> ⏳ Pendente
B7: 4. Lançamento Comercial | C7: 46143 | E7: =IF(D7="","",D7-C7) | F7: =IF(D7="","⏳ Pendente",IF(D7<=C7,"✅ No Prazo",IF(D7-C7<=15,"⚠️ Atraso Leve","🔴 Atrasado"))) -> ⏳ Pendente
B8: 5. Obra — Início | C8: 46204 | E8: =IF(D8="","",D8-C8) | F8: =IF(D8="","⏳ Pendente",IF(D8<=C8,"✅ No Prazo",IF(D8-C8<=15,"⚠️ Atraso Leve","🔴 Atrasado"))) -> ⏳ Pendente
B9: 6. Obra — Conclusão | C9: 46753 | E9: =IF(D9="","",D9-C9) | F9: =IF(D9="","⏳ Pendente",IF(D9<=C9,"✅ No Prazo",IF(D9-C9<=15,"⚠️ Atraso Leve","🔴 Atrasado"))) -> ⏳ Pendente
B10: 7. Habite-se | C10: 46784 | E10: =IF(D10="","",D10-C10) | F10: =IF(D10="","⏳ Pendente",IF(D10<=C10,"✅ No Prazo",IF(D10-C10<=15,"⚠️ Atraso Leve","🔴 Atrasado"))) -> ⏳ Pendente
B11: 8. Entrega de Chaves | C11: 46935 | E11: =IF(D11="","",D11-C11) | F11: =IF(D11="","⏳ Pendente",IF(D11<=C11,"✅ No Prazo",IF(D11-C11<=15,"⚠️ Atraso Leve","🔴 Atrasado"))) -> ⏳ Pendente
B13: RESUMO DE PRAZO
B14: Início Planejado | F14: =C4 -> 46023
B15: Entrega Planejada | F15: =C11 -> 46935
B16: Prazo Total Planejado (dias) | F16: =C11-C4 -> 912
B17: Prazo Total Realizado (dias) | F17: =IF(D11="","-",D11-D4) -> -
B18: Desvio Total (dias) | F18: =IF(E11="","-",SUM(E4:E11)) -> -

Sheet FORNECEDORES
A1: 🏗️ FORNECEDORES — SCORE DE RISCO (CUSTO + PRAZO)
A2: Pesos: Custo = CONFIG!C20 | Prazo = CONFIG!C21 | Score = (Desv. Custo% × Peso) + (Desv. Prazo% × Peso) × 100
B3: FORNECEDOR | C3: CATEGORIA | D3: VALOR ORÇADO | E3: VALOR REALIZADO | F3: PRAZO PREV.(dias) | G3: PRAZO REAL(dias) | H3: DESV. CUSTO % | I3: DESV. PRAZO % | J3: SCORE | K3: RANK
B4: Construtora ABC | C4: Obra Civil | D4: 5800000 | E4: 1950000 | F4: 540 | G4: 565 | H4: =IFERROR(MAX(0,(E4-D4)/D4),0) -> 0 | I4: =IFERROR(MAX(0,(G4-F4)/F4),0) -> 0.046296296 | J4: =IFERROR((H4*CONFIG!$C$20 + I4*CONFIG!$C$21)*100,0) -> 2.3148148 | K4: =IF(B4="","",RANK(J4,$J$4:$J$23,0)) -> 6
B5: Inst. Elétrica Ltda | C5: Instalações | D5: 450000 | E5: 185000 | F5: 120 | G5: 128 | H5: =IFERROR(MAX(0,(E5-D5)/D5),0) -> 0 | I5: =IFERROR(MAX(0,(G5-F5)/F5),0) -> 0.066666667 | J5: =IFERROR((H5*CONFIG!$C$20 + I5*CONFIG!$C$21)*100,0) -> 3.3333333 | K5: =IF(B5="","",RANK(J5,$J$4:$J$23,0)) -> 5
B6: Inst. Hidráulica SP | C6: Instalações | D6: 400000 | E6: 125000 | F6: 90 | G6: 90 | H6: =IFERROR(MAX(0,(E6-D6)/D6),0) -> 0 | I6: =IFERROR(MAX(0,(G6-F6)/F6),0) -> 0 | J6: =IFERROR((H6*CONFIG!$C$20 + I6*CONFIG!$C$21)*100,0) -> 0 | K6: =IF(B6="","",RANK(J6,$J$4:$J$23,0)) -> 7
B7: Escritório Arq. XYZ | C7: Projetos | D7: 180000 | E7: 210000 | F7: 60 | G7: 75 | H7: =IFERROR(MAX(0,(E7-D7)/D7),0) -> 0.16666667 | I7: =IFERROR(MAX(0,(G7-F7)/F7),0) -> 0.25 | J7: =IFERROR((H7*CONFIG!$C$20 + I7*CONFIG!$C$21)*100,0) -> 20.833333 | K7: =IF(B7="","",RANK(J7,$J$4:$J$23,0)) -> 2
B8: Topografia & Sondagem | C8: Outros | D8: 60000 | E8: 65000 | F8: 30 | G8: 35 | H8: =IFERROR(MAX(0,(E8-D8)/D8),0) -> 0.083333333 | I8: =IFERROR(MAX(0,(G8-F8)/F8),0) -> 0.16666667 | J8: =IFERROR((H8*CONFIG!$C$20 + I8*CONFIG!$C$21)*100,0) -> 12.5 | K8: =IF(B8="","",RANK(J8,$J$4:$J$23,0)) -> 4
B9: Agência Digital | C9: Marketing | D9: 150000 | E9: 130000 | F9: 120 | G9: 120 | H9: =IFERROR(MAX(0,(E9-D9)/D9),0) -> 0 | I9: =IFERROR(MAX(0,(G9-F9)/F9),0) -> 0 | J9: =IFERROR((H9*CONFIG!$C$20 + I9*CONFIG!$C$21)*100,0) -> 0 | K9: =IF(B9="","",RANK(J9,$J$4:$J$23,0)) -> 7
B10: Corretora SP Imóveis | C10: Comercialização | D10: 595000 | E10: 210000 | F10: 540 | G10: 540 | H10: =IFERROR(MAX(0,(E10-D10)/D10),0) -> 0 | I10: =IFERROR(MAX(0,(G10-F10)/F10),0) -> 0 | J10: =IFERROR((H10*CONFIG!$C$20 + I10*CONFIG!$C$21)*100,0) -> 0 | K10: =IF(B10="","",RANK(J10,$J$4:$J$23,0)) -> 7
B11: Banco CEF | C11: Financeiro | D11: 405000 | E11: 95000 | F11: 540 | G11: 540 | H11: =IFERROR(MAX(0,(E11-D11)/D11),0) -> 0 | I11: =IFERROR(MAX(0,(G11-F11)/F11),0) -> 0 | J11: =IFERROR((H11*CONFIG!$C$20 + I11*CONFIG!$C$21)*100,0) -> 0 | K11: =IF(B11="","",RANK(J11,$J$4:$J$23,0)) -> 7
B12: Assessoria Jurídica | C12: Aprovações | D12: 80000 | E12: 90000 | F12: 45 | G12: 62 | H12: =IFERROR(MAX(0,(E12-D12)/D12),0) -> 0.125 | I12: =IFERROR(MAX(0,(G12-F12)/F12),0) -> 0.37777778 | J12: =IFERROR((H12*CONFIG!$C$20 + I12*CONFIG!$C$21)*100,0) -> 25.138889 | K12: =IF(B12="","",RANK(J12,$J$4:$J$23,0)) -> 1
B13: Gráfica & Comunicação | C13: Marketing | D13: 40000 | E13: 50000 | F13: 20 | G13: 22 | H13: =IFERROR(MAX(0,(E13-D13)/D13),0) -> 0.25 | I13: =IFERROR(MAX(0,(G13-F13)/F13),0) -> 0.1 | J13: =IFERROR((H13*CONFIG!$C$20 + I13*CONFIG!$C$21)*100,0) -> 17.5 | K13: =IF(B13="","",RANK(J13,$J$4:$J$23,0)) -> 3
H14: =IFERROR(MAX(0,(E14-D14)/D14),0) -> 0 | I14: =IFERROR(MAX(0,(G14-F14)/F14),0) -> 0 | J14: =IFERROR((H14*CONFIG!$C$20+I14*CONFIG!$C$21)*100,0) -> 0 | K14: =IF(B14="","",RANK(J14,$J$4:$J$23,0))
H15: =IFERROR(MAX(0,(E15-D15)/D15),0) -> 0 | I15: =IFERROR(MAX(0,(G15-F15)/F15),0) -> 0 | J15: =IFERROR((H15*CONFIG!$C$20+I15*CONFIG!$C$21)*100,0) -> 0 | K15: =IF(B15="","",RANK(J15,$J$4:$J$23,0))
H16: =IFERROR(MAX(0,(E16-D16)/D16),0) -> 0 | I16: =IFERROR(MAX(0,(G16-F16)/F16),0) -> 0 | J16: =IFERROR((H16*CONFIG!$C$20+I16*CONFIG!$C$21)*100,0) -> 0 | K16: =IF(B16="","",RANK(J16,$J$4:$J$23,0))
H17: =IFERROR(MAX(0,(E17-D17)/D17),0) -> 0 | I17: =IFERROR(MAX(0,(G17-F17)/F17),0) -> 0 | J17: =IFERROR((H17*CONFIG!$C$20+I17*CONFIG!$C$21)*100,0) -> 0 | K17: =IF(B17="","",RANK(J17,$J$4:$J$23,0))
H18: =IFERROR(MAX(0,(E18-D18)/D18),0) -> 0 | I18: =IFERROR(MAX(0,(G18-F18)/F18),0) -> 0 | J18: =IFERROR((H18*CONFIG!$C$20+I18*CONFIG!$C$21)*100,0) -> 0 | K18: =IF(B18="","",RANK(J18,$J$4:$J$23,0))
H19: =IFERROR(MAX(0,(E19-D19)/D19),0) -> 0 | I19: =IFERROR(MAX(0,(G19-F19)/F19),0) -> 0 | J19: =IFERROR((H19*CONFIG!$C$20+I19*CONFIG!$C$21)*100,0) -> 0 | K19: =IF(B19="","",RANK(J19,$J$4:$J$23,0))
H20: =IFERROR(MAX(0,(E20-D20)/D20),0) -> 0 | I20: =IFERROR(MAX(0,(G20-F20)/F20),0) -> 0 | J20: =IFERROR((H20*CONFIG!$C$20+I20*CONFIG!$C$21)*100,0) -> 0 | K20: =IF(B20="","",RANK(J20,$J$4:$J$23,0))
H21: =IFERROR(MAX(0,(E21-D21)/D21),0) -> 0 | I21: =IFERROR(MAX(0,(G21-F21)/F21),0) -> 0 | J21: =IFERROR((H21*CONFIG!$C$20+I21*CONFIG!$C$21)*100,0) -> 0 | K21: =IF(B21="","",RANK(J21,$J$4:$J$23,0))
H22: =IFERROR(MAX(0,(E22-D22)/D22),0) -> 0 | I22: =IFERROR(MAX(0,(G22-F22)/F22),0) -> 0 | J22: =IFERROR((H22*CONFIG!$C$20+I22*CONFIG!$C$21)*100,0) -> 0 | K22: =IF(B22="","",RANK(J22,$J$4:$J$23,0))
H23: =IFERROR(MAX(0,(E23-D23)/D23),0) -> 0 | I23: =IFERROR(MAX(0,(G23-F23)/F23),0) -> 0 | J23: =IFERROR((H23*CONFIG!$C$20+I23*CONFIG!$C$21)*100,0) -> 0 | K23: =IF(B23="","",RANK(J23,$J$4:$J$23,0))

Sheet DESEMBOLSO
A1: 📊 DESEMBOLSO — CURVA MENSAL DE SAÍDA DE CAIXA (R$)
A2: Insira os valores mensais de desembolso por categoria. Totais e acumulado são calculados automaticamente.
A3: CATEGORIA | C3: Mês 1 | D3: Mês 2 | E3: Mês 3 | F3: Mês 4 | G3: Mês 5 | H3: Mês 6 | I3: Mês 7 | J3: Mês 8 | K3: Mês 9 | L3: Mês 10 | M3: Mês 11 | N3: Mês 12 | O3: Mês 13 | P3: Mês 14 | Q3: Mês 15 | R3: Mês 16 | S3: Mês 17 | T3: Mês 18 | U3: Mês 19 | V3: Mês 20 | W3: Mês 21 | X3: Mês 22 | Y3: Mês 23 | Z3: Mês 24 | AA3: Mês 25 | AB3: Mês 26 | AC3: Mês 27 | AD3: Mês 28 | AE3: Mês 29 | AF3: Mês 30 | AG3: Mês 31 | AH3: Mês 32 | AI3: Mês 33 | AJ3: Mês 34 | AK3: Mês 35 | AL3: Mês 36
A4: Terreno | C4: 2500000
A5: Projetos e Aprovações | C5: 80000 | D5: 100000 | E5: 120000 | F5: 50000
A6: Obra Civil | G6: 150000 | H6: 250000 | I6: 380000 | J6: 420000 | K6: 350000 | L6: 200000
A7: Instalações | I7: 50000 | J7: 80000 | K7: 120000 | L7: 60000
A8: Marketing | E8: 50000 | F8: 80000 | G8: 50000
A9: Comercialização | G9: 50000 | H9: 80000 | I9: 80000
A10: Financeiro (Juros/CET) | H10: 20000 | I10: 25000 | J10: 25000 | K10: 25000
A11: Outros | C11: 30000 | D11: 20000 | G11: 50000 | H11: 25000
A12: TOTAL MENSAL | C12: =SUM(C4:C11) -> 2610000 | D12: =SUM(D4:D11) -> 120000 | E12: =SUM(E4:E11) -> 170000 | F12: =SUM(F4:F11) -> 130000 | G12: =SUM(G4:G11) -> 300000 | H12: =SUM(H4:H11) -> 375000 | I12: =SUM(I4:I11) -> 535000 | J12: =SUM(J4:J11) -> 525000 | ... AL12: =SUM(AL4:AL11) -> 0
A13: ACUMULADO | C13: =C12 -> 2610000 | D13: =C13+D12 -> 2730000 | E13: =D13+E12 -> 2900000 | F13: =E13+F12 -> 3030000 | G13: =F13+G12 -> 3330000 | H13: =G13+H12 -> 3705000 | I13: =H13+I12 -> 4240000 | J13: =I13+J12 -> 4765000 | K13: =J13+K12 -> 5260000 | ... AL13: =AK13+AL12 -> 5520000
A14: MÊS ATUAL (✔) | C14: =IF(AND(YEAR(TODAY())=YEAR(EDATE(CONFIG!$C$6,1-1)),MONTH(TODAY())=MONTH(EDATE(CONFIG!$C$6,1-1))),"◀ ATUAL","") | D14: =IF(AND(YEAR(TODAY())=YEAR(EDATE(CONFIG!$C$6,2-1)),MONTH(TODAY())=MONTH(EDATE(CONFIG!$C$6,2-1))),"◀ ATUAL","") | E14: =IF(AND(YEAR(TODAY())=YEAR(EDATE(CONFIG!$C$6,3-1)),MONTH(TODAY())=MONTH(EDATE(CONFIG!$C$6,3-1))),"◀ ATUAL","") -> ◀ ATUAL | F14: =IF(AND(YEAR(TODAY())=YEAR(EDATE(CONFIG!$C$6,4-1)),MONTH(TODAY())=MONTH(EDATE(CONFIG!$C$6,4-1))),"◀ ATUAL","") | G14: =IF(AND(YEAR(TODAY())=YEAR(EDATE(CONFIG!$C$6,5-1)),MONTH(TODAY())=MONTH(EDATE(CONFIG!$C$6,5-1))),"◀ ATUAL","") | H14: =IF(AND(YEAR(TODAY())=YEAR(EDATE(CONFIG!$C$6,6-1)),MONTH(TODAY())=MONTH(EDATE(CONFIG!$C$6,6-1))),"◀ ATUAL","") | I14: =IF(AND(YEAR(TODAY())=YEAR(EDATE(CONFIG!$C$6,7-1)),MONTH(TODAY())=MONTH(EDATE(CONFIG!$C$6,7-1))),"◀ ATUAL","") | J14: =IF(AND(YEAR(TODAY())=YEAR(EDATE(CONFIG!$C$6,8-1)),MONTH(TODAY())=MONTH(EDATE(CONFIG!$C$6,8-1))),"◀ ATUAL","") | K14: =IF(AND(YEAR(TODAY())=YEAR(EDATE(CONFIG!$C$6,9-1)),MONTH(TODAY())=MONTH(EDATE(CONFIG!$C$6,9-1))),"◀ ATUAL","") | L14: =IF(AND(YEAR(TODAY())=YEAR(EDATE(CONFIG!$C$6,10-1)),MONTH(TODAY())=MONTH(EDATE(CONFIG!$C$6,10-1))),"◀ ATUAL","") | M14: =IF(AND(YEAR(TODAY())=YEAR(EDATE(CONFIG!$C$6,11-1)),MONTH(TODAY())=MONTH(EDATE(CONFIG!$C$6,11-1))),"◀ ATUAL","") | N14: =IF(AND(YEAR(TODAY())=YEAR(EDATE(CONFIG!$C$6,12-1)),MONTH(TODAY())=MONTH(EDATE(CONFIG!$C$6,12-1))),"◀ ATUAL","") | O14: =IF(AND(YEAR(TODAY())=YEAR(EDATE(CONFIG!$C$6,13-1)),MONTH(TODAY())=MONTH(EDATE(CONFIG!$C$6,13-1))),"◀ ATUAL","") | P14: =IF(AND(YEAR(TODAY())=YEAR(EDATE(CONFIG!$C$6,14-1)),MONTH(TODAY())=MONTH(EDATE(CONFIG!$C$6,14-1))),"◀ ATUAL","") | Q14: =IF(AND(YEAR(TODAY())=YEAR(EDATE(CONFIG!$C$6,15-1)),MONTH(TODAY())=MONTH(EDATE(CONFIG!$C$6,15-1))),"◀ ATUAL","") | R14: =IF(AND(YEAR(TODAY())=YEAR(EDATE(CONFIG!$C$6,16-1)),MONTH(TODAY())=MONTH(EDATE(CONFIG!$C$6,16-1))),"◀ ATUAL","") | S14: =IF(AND(YEAR(TODAY())=YEAR(EDATE(CONFIG!$C$6,17-1)),MONTH(TODAY())=MONTH(EDATE(CONFIG!$C$6,17-1))),"◀ ATUAL","") | T14: =IF(AND(YEAR(TODAY())=YEAR(EDATE(CONFIG!$C$6,18-1)),MONTH(TODAY())=MONTH(EDATE(CONFIG!$C$6,18-1))),"◀ ATUAL","") | U14: =IF(AND(YEAR(TODAY())=YEAR(EDATE(CONFIG!$C$6,19-1)),MONTH(TODAY())=MONTH(EDATE(CONFIG!$C$6,19-1))),"◀ ATUAL","") | V14: =IF(AND(YEAR(TODAY())=YEAR(EDATE(CONFIG!$C$6,20-1)),MONTH(TODAY())=MONTH(EDATE(CONFIG!$C$6,20-1))),"◀ ATUAL","") | W14: =IF(AND(YEAR(TODAY())=YEAR(EDATE(CONFIG!$C$6,21-1)),MONTH(TODAY())=MONTH(EDATE(CONFIG!$C$6,21-1))),"◀ ATUAL","") | X14: =IF(AND(YEAR(TODAY())=YEAR(EDATE(CONFIG!$C$6,22-1)),MONTH(TODAY())=MONTH(EDATE(CONFIG!$C$6,22-1))),"◀ ATUAL","") | Y14: =IF(AND(YEAR(TODAY())=YEAR(EDATE(CONFIG!$C$6,23-1)),MONTH(TODAY())=MONTH(EDATE(CONFIG!$C$6,23-1))),"◀ ATUAL","") | Z14: =IF(AND(YEAR(TODAY())=YEAR(EDATE(CONFIG!$C$6,24-1)),MONTH(TODAY())=MONTH(EDATE(CONFIG!$C$6,24-1))),"◀ ATUAL","") | AA14: =IF(AND(YEAR(TODAY())=YEAR(EDATE(CONFIG!$C$6,25-1)),MONTH(TODAY())=MONTH(EDATE(CONFIG!$C$6,25-1))),"◀ ATUAL","") | AB14: =IF(AND(YEAR(TODAY())=YEAR(EDATE(CONFIG!$C$6,26-1)),MONTH(TODAY())=MONTH(EDATE(CONFIG!$C$6,26-1))),"◀ ATUAL","") | AC14: =IF(AND(YEAR(TODAY())=YEAR(EDATE(CONFIG!$C$6,27-1)),MONTH(TODAY())=MONTH(EDATE(CONFIG!$C$6,27-1))),"◀ ATUAL","") | AD14: =IF(AND(YEAR(TODAY())=YEAR(EDATE(CONFIG!$C$6,28-1)),MONTH(TODAY())=MONTH(EDATE(CONFIG!$C$6,28-1))),"◀ ATUAL","") | AE14: =IF(AND(YEAR(TODAY())=YEAR(EDATE(CONFIG!$C$6,29-1)),MONTH(TODAY())=MONTH(EDATE(CONFIG!$C$6,29-1))),"◀ ATUAL","") | AF14: =IF(AND(YEAR(TODAY())=YEAR(EDATE(CONFIG!$C$6,30-1)),MONTH(TODAY())=MONTH(EDATE(CONFIG!$C$6,30-1))),"◀ ATUAL","") | AG14: =IF(AND(YEAR(TODAY())=YEAR(EDATE(CONFIG!$C$6,31-1)),MONTH(TODAY())=MONTH(EDATE(CONFIG!$C$6,31-1))),"◀ ATUAL","") | AH14: =IF(AND(YEAR(TODAY())=YEAR(EDATE(CONFIG!$C$6,32-1)),MONTH(TODAY())=MONTH(EDATE(CONFIG!$C$6,32-1))),"◀ ATUAL","") | AI14: =IF(AND(YEAR(TODAY())=YEAR(EDATE(CONFIG!$C$6,33-1)),MONTH(TODAY())=MONTH(EDATE(CONFIG!$C$6,33-1))),"◀ ATUAL","") | AJ14: =IF(AND(YEAR(TODAY())=YEAR(EDATE(CONFIG!$C$6,34-1)),MONTH(TODAY())=MONTH(EDATE(CONFIG!$C$6,34-1))),"◀ ATUAL","") | AK14: =IF(AND(YEAR(TODAY())=YEAR(EDATE(CONFIG!$C$6,35-1)),MONTH(TODAY())=MONTH(EDATE(CONFIG!$C$6,35-1))),"◀ ATUAL","") | AL14: =IF(AND(YEAR(TODAY())=YEAR(EDATE(CONFIG!$C$6,36-1)),MONTH(TODAY())=MONTH(EDATE(CONFIG!$C$6,36-1))),"◀ ATUAL","")
